<?xml version="1.0" ?>
<!-- =================================================================================== -->
<!-- |    This document was autogenerated by xacro from /home/drims/catkin_ws/src/DRIMS_volterra/drims_dice_demo/xacro/robot_arm.urdf.xacro | -->
<!-- |    EDITING THIS FILE BY HAND IS NOT RECOMMENDED                                 | -->
<!-- =================================================================================== -->
<robot name="robot">
    <!-- <xacro:arg name="gripper_interface" default="hardware_interface/PositionJointInterface" /> -->
    <material name="Black">
        <color rgba="0.0 0.0 0.0 1.0" />
    </material>
    <material name="Blue">
        <color rgba="0.0 0.0 0.8 1.0" />
    </material>
    <material name="Green">
        <color rgba="0.0 0.8 0.0 1.0" />
    </material>
    <material name="Grey">
        <color rgba="0.5 0.5 0.5 1.0" />
    </material>
    <material name="Light_Grey">
        <color rgba="0.8 0.8 0.8 1.0" />
    </material>
    <material name="Ivory">
        <color rgba="1.0 1.0 0.94 1.0" />
    </material>
    <material name="Orange">
        <color rgba="1.0 0.4235294117647059 0.0392156862745098 1.0" />
    </material>
    <material name="Brown">
        <color rgba="0.8705882352941177 0.8117647058823529 0.7647058823529411 1.0" />
    </material>
    <material name="Red">
        <color rgba="0.8 0.0 0.0 1.0" />
    </material>
    <material name="White">
        <color rgba="1.0 1.0 1.0 1.0" />
    </material>
    <gazebo reference="base_link_table">
        <mu1>0.2</mu1>
        <mu2>0.1</mu2>
        <plugin name="gazebo_ros_control" filename="libgazebo_ros_control.so">
            <robotNamespace>/</robotNamespace>
        </plugin>
    </gazebo>
    <!-- 72 52 2 -->
    <!-- GoFa color -->
    <material name="gofa_color">
        <color rgba="0.792156862745098 0.819607843137255 0.933333333333333 1" />
    </material>
    <!-- World fixed joint -->
    <link name="world" />
    <!-- <material name="yellow">
            <color rgba="255.0 255.0 0.0 1"/>
        </material> -->
    <joint name="joint_table_robot" type="fixed">
        <origin rpy="0 0 0" xyz="0 0 0" />
        <parent link="world" />
        <child link="base_link_table" />
    </joint>
    <gazebo reference="base_link_table">
        <material>Gazebo/Grey</material>
    </gazebo>
    <link name="base_link_table">
        <contact>
            <lateral_friction value="1.0" />
        </contact>
        <inertial>
            <origin rpy="0 0 0" xyz="0 0 0" />
            <mass value=".0" />
            <inertia ixx="1" ixy="0" ixz="0" iyy="1" iyz="0" izz="1" />
        </inertial>
        <visual>
            <origin rpy="0 0 0" xyz="0 0 0.6" />
            <geometry>
                <mesh filename="package://drims_dice_demo/meshes/Extra/table.obj" scale="1.5 1 0.05" />
            </geometry>
            <!-- <material name="Gazebo/Yellow"/> -->
        </visual>
        <collision>
            <origin rpy="0 0 0" xyz="0 0 0.6" />
            <geometry>
                <mesh filename="package://drims_dice_demo/meshes/Extra/table.obj" scale="1.5 1 0.05" />
            </geometry>
            <!-- <material name="Gazebo/Yellow"/> -->
        </collision>
        <!-- <collision>
                <origin rpy="0 0 0" xyz="0 0 0.6"/>
                <geometry>
                    <box size="1.5 1 0.05"/>
                </geometry>
            </collision> -->
        <visual>
            <origin rpy="0 0 0" xyz="-0.65 -0.4 0.29" />
            <geometry>
                <mesh filename="package://drims_dice_demo/meshes/Extra/table.obj" scale="0.1 0.1 0.58" />
            </geometry>
            <!-- <material name="white">
                    <color rgba="1 1 1 1"/>
                </material>	  -->
        </visual>
        <visual>
            <origin rpy="0 0 0" xyz="-0.65 0.4 0.29" />
            <geometry>
                <mesh filename="package://drims_dice_demo/meshes/Extra/table.obj" scale="0.1 0.1 0.58" />
            </geometry>
            <!-- <material name="white">
                    <color rgba="1 1 1 1"/>
                </material>	  -->
        </visual>
        <visual>
            <origin rpy="0 0 0" xyz="0.65 -0.4 0.29" />
            <geometry>
                <mesh filename="package://drims_dice_demo/meshes/Extra/table.obj" scale="0.1 0.1 0.58" />
            </geometry>
            <!-- <material name="white">
                    <color rgba="1 1 1 1"/>
                </material>	  -->
        </visual>
        <visual>
            <origin rpy="0 0 0" xyz="0.65 0.4 0.29" />
            <geometry>
                <mesh filename="package://drims_dice_demo/meshes/Extra/table.obj" scale="0.1 0.1 0.58" />
            </geometry>
        </visual>
    </link>
    <joint name="joint_camera_stand_robot" type="fixed">
        <origin rpy="0 0 0" xyz="0.0 0.4 0.65" />
        <parent link="base_link_table" />
        <child link="base_link_camera_stand" />
    </joint>
    <link name="base_link_camera_stand">
        <inertial>
            <origin rpy="0 0 0" xyz="0 0 0" />
            <mass value="1.0" />
            <inertia ixx="1" ixy="0" ixz="0" iyy="1" iyz="0" izz="1" />
        </inertial>
        <visual>
            <origin rpy="0 0 0" xyz="0 0 0.44" />
            <geometry>
                <box size="0.04 0.04 0.88" />
            </geometry>
        </visual>
        <collision>
            <origin rpy="0 0 0" xyz="0 0 0.44" />
            <geometry>
                <box size="0.04 0.04 0.88" />
            </geometry>
        </collision>
    </link>
    <link name="camera_holder">
        <inertial>
            <origin rpy="0 0 0" xyz="0 0 0" />
            <mass value="1.0" />
            <inertia ixx="1" ixy="0" ixz="0" iyy="1" iyz="0" izz="1" />
        </inertial>
        <visual>
            <origin rpy="0 0 0" xyz="0 0 0.15" />
            <geometry>
                <box size="0.04 0.04 0.3" />
            </geometry>
        </visual>
        <collision>
            <origin rpy="0 0 0" xyz="0 0 0.15" />
            <geometry>
                <box size="0.1 0.1 0.3" />
            </geometry>
        </collision>
    </link>
    <joint name="joint_camera_holder" type="fixed">
        <origin rpy="1.5707963267948966 -1.5707963267948966 0" xyz="0.0 0.0 0.88" />
        <parent link="base_link_camera_stand" />
        <child link="camera_holder" />
    </joint>
    <link name="ext_camera_link">
        <visual>
            <origin rpy="0 0 0" xyz="0 0 0" />
            <geometry>
                <box size="0.01 0.01 0.01" />
            </geometry>
            <material name="Red" />
        </visual>
        <inertial>
            <mass value="1e-5" />
            <origin rpy="0 0 0" xyz="0 0 0" />
            <inertia ixx="1e-6" ixy="0" ixz="0" iyy="1e-6" iyz="0" izz="1e-6" />
        </inertial>
    </link>
    <joint name="joint_camera_link" type="fixed">
        <origin rpy="-1.5707963267948966 0 -3.14 " xyz="0.0 0.0 0.4" />
        <parent link="camera_holder" />
        <child link="ext_camera_link" />
    </joint>
    <gazebo reference="ext_camera_link">
        <sensor name="camera1" type="camera">
            <update_rate>5.0</update_rate>
            <camera name="head">
                <horizontal_fov>1.01</horizontal_fov>
                <image>
                    <width>1280</width>
                    <height>720</height>
                    <format>R8G8B8</format>
                </image>
                <clip>
                    <near>0.02</near>
                    <far>300</far>
                </clip>
                <noise>
                    <type>gaussian</type>
                    <!-- Noise is sampled independently per pixel on each frame.
                        That pixel's noise value is added to each of its color
                        channels, which at that point lie in the range [0,1]. -->
                    <mean>0.0</mean>
                    <stddev>0.007</stddev>
                </noise>
            </camera>
            <plugin filename="libgazebo_ros_camera.so" name="camera_controller">
                <alwaysOn>true</alwaysOn>
                <updateRate>5.0</updateRate>
                <cameraName>camera</cameraName>
                <imageTopicName>/oak/rgb/image_raw</imageTopicName>
                <cameraInfoTopicName>camera_info</cameraInfoTopicName>
                <frameName>ext_camera_link</frameName>
                <!-- <hackBaseline>0.07</hackBaseline> -->
                <distortionK1>0.000001</distortionK1>
                <distortionK2>0.000001</distortionK2>
                <distortionK3>0.000001</distortionK3>
                <distortionT1>0.000001</distortionT1>
                <distortionT2>0.000001</distortionT2>
            </plugin>
        </sensor>
    </gazebo>
    <joint name="joint_surface_robot" type="fixed">
        <origin rpy="0 0 0" xyz="-0.03 0.33 0.08" />
        <parent link="yumi_base_link" />
        <child link="base_link_surface" />
    </joint>
    <gazebo reference="base_link_surface">
        <material>Gazebo/Green</material>
    </gazebo>
    <link name="base_link_surface">
        <inertial>
            <origin rpy="0 0 0" xyz="0 0 0" />
            <mass value="1.0" />
            <inertia ixx="1" ixy="0" ixz="0" iyy="1" iyz="0" izz="1" />
        </inertial>
        <visual>
            <origin rpy="0 0 0" xyz="0 0 0" />
            <geometry>
                <box size="0.6 0.4 0.1" />
            </geometry>
        </visual>
        <collision>
            <origin rpy="0 0 0" xyz="0 0 0" />
            <geometry>
                <box size="0.6 0.4 0.1" />
            </geometry>
        </collision>
    </link>
    <!-- Choose between gofa and yumi_single_arm -->
    <!-- joint between external and base -->
    <joint name="joint_0" type="fixed">
        <origin rpy="0 0 -1.57" xyz="-0.3 0 0.6" />
        <parent link="base_link_table" />
        <child link="yumi_base_link" />
    </joint>
    <link name="yumi_base_link">
        <visual>
            <origin rpy="0 0 0" xyz="0 0 0" />
            <geometry>
                <mesh filename="package://omnicore_description/meshes/Yumi/single_arm_base.stl" />
            </geometry>
            <material name="Grey" />
        </visual>
        <!-- <collision>
        <origin xyz="0 0 0" rpy="0 0 0" />
        <geometry>
          <mesh filename="package://omnicore_description/meshes/Yumi/single_arm_base.stl" />
        </geometry>
        <material name="Grey" />
      </collision> -->
        <inertial>
            <origin rpy="0 0 0" xyz="0 0 0" />
            <mass value="0.1" />
            <inertia ixx="0.1" ixy="0" ixz="0" iyy="0.1" iyz="0" izz="0.1" />
        </inertial>
    </link>
    <!-- joint between body and link_1 -->
    <joint name="joint_1" type="revolute">
        <parent link="yumi_base_link" />
        <child link="link_1" />
        <origin rpy="0.0 0.0 3.141592653589793" xyz="0.0 0.0 0.2048" />
        <axis xyz="0 0 1" />
        <limit effort="300" lower="-2.940879789610445" upper="2.940879789610445" velocity="3.141592653589793" />
        <dynamics damping="0.5" />
    </joint>
    <link name="link_1">
        <inertial>
            <origin rpy="0 0 0" xyz="0 -0.03 0.12" />
            <mass value="2" />
            <inertia ixx="0.1" ixy="0" ixz="0" iyy="0.1" iyz="0" izz="0.1" />
        </inertial>
        <visual>
            <origin rpy="0 0 0" xyz="0 0 0" />
            <geometry>
                <mesh filename="package://omnicore_description/meshes/Yumi/link_1.stl" />
            </geometry>
            <material name="Grey" />
        </visual>
        <collision>
            <origin rpy="0 0 0" xyz="0 0 0" />
            <geometry>
                <mesh filename="package://omnicore_description/meshes/Yumi/coarse/link_1.stl" />
            </geometry>
            <material name="Grey" />
        </collision>
    </link>
    <!-- joint between link_1 and link_2 -->
    <joint name="joint_2" type="revolute">
        <parent link="link_1" />
        <child link="link_2" />
        <origin rpy="1.5707963267948966 0.0 0.0" xyz="0.03 0.0 0.1" />
        <axis xyz="0 0 1" />
        <limit effort="300" lower="-2.504547476611863" upper="0.7592182246175333" velocity="3.141592653589793" />
        <dynamics damping="0.5" />
    </joint>
    <link name="link_2">
        <inertial>
            <origin rpy="0 0 0" xyz="0 0 0" />
            <mass value="2" />
            <inertia ixx="0.1" ixy="0" ixz="0" iyy="0.1" iyz="0" izz="0.1" />
        </inertial>
        <visual>
            <origin rpy="0 0 0" xyz="0 0 0" />
            <geometry>
                <mesh filename="package://omnicore_description/meshes/Yumi/link_2.stl" />
            </geometry>
            <material name="Grey" />
        </visual>
        <collision>
            <origin rpy="0 0 0" xyz="0 0 0" />
            <geometry>
                <mesh filename="package://omnicore_description/meshes/Yumi/coarse/link_2.stl" />
            </geometry>
            <material name="Grey" />
        </collision>
    </link>
    <!-- joint between link_2 and link_3 -->
    <joint name="joint_3" type="revolute">
        <parent link="link_2" />
        <child link="link_3" />
        <origin rpy="-1.5707963267948966 0.0 0.0" xyz="-0.03 0.17283 0.0" />
        <axis xyz="0 0 1" />
        <limit effort="300" lower="-2.940879789610445" upper="2.940879789610445" velocity="3.141592653589793" />
        <dynamics damping="0.5" />
    </joint>
    <link name="link_3">
        <inertial>
            <origin rpy="0 0 0" xyz="0 0 0" />
            <mass value="2" />
            <inertia ixx="0.1" ixy="0" ixz="0" iyy="0.1" iyz="0" izz="0.1" />
        </inertial>
        <visual>
            <origin rpy="0 0 0" xyz="0 0 0" />
            <geometry>
                <mesh filename="package://omnicore_description/meshes/Yumi/link_3.stl" />
            </geometry>
            <material name="Grey" />
        </visual>
        <collision>
            <origin rpy="0 0 0" xyz="0 0 0" />
            <geometry>
                <mesh filename="package://omnicore_description/meshes/Yumi/coarse/link_3.stl" />
            </geometry>
            <material name="Grey" />
        </collision>
    </link>
    <!-- joint between link_3 and link_4 -->
    <joint name="joint_4" type="revolute">
        <parent link="link_3" />
        <child link="link_4" />
        <origin rpy="1.5707963267948966 -1.5707963267948966 0.0" xyz="-0.04188 0.0 0.07873" />
        <axis xyz="0 0 1" />
        <limit effort="300" lower="-2.155481626212997" upper="1.3962634015954636" velocity="3.141592653589793" />
        <dynamics damping="0.5" />
    </joint>
    <link name="link_4">
        <inertial>
            <origin rpy="0 0 0" xyz="0 0 0" />
            <mass value="2" />
            <inertia ixx="0.1" ixy="0" ixz="0" iyy="0.1" iyz="0" izz="0.1" />
        </inertial>
        <visual>
            <origin rpy="0 0 0" xyz="0 0 0" />
            <geometry>
                <mesh filename="package://omnicore_description/meshes/Yumi/link_4.stl" />
            </geometry>
            <material name="Grey" />
        </visual>
        <collision>
            <origin rpy="0 0 0" xyz="0 0 0" />
            <geometry>
                <mesh filename="package://omnicore_description/meshes/Yumi/coarse/link_4.stl" />
            </geometry>
            <material name="Grey" />
        </collision>
    </link>
    <!-- joint between link_4 and link_5 -->
    <joint name="joint_5" type="revolute">
        <parent link="link_4" />
        <child link="link_5" />
        <origin rpy="-1.5707963267948966 0.0 0.0" xyz="0.0405 0.16461 0.0" />
        <axis xyz="0 0 1" />
        <limit effort="300" lower="-5.061454830783555" upper="5.061454830783555" velocity="6.981317007977318" />
        <dynamics damping="0.5" />
    </joint>
    <link name="link_5">
        <inertial>
            <origin rpy="0 0 0" xyz="0 0 0" />
            <mass value="2" />
            <inertia ixx="0.1" ixy="0" ixz="0" iyy="0.1" iyz="0" izz="0.1" />
        </inertial>
        <visual>
            <origin rpy="0 0 0" xyz="0 0 0" />
            <geometry>
                <mesh filename="package://omnicore_description/meshes/Yumi/link_5.stl" />
            </geometry>
            <material name="Grey" />
        </visual>
        <collision>
            <origin rpy="0 0 0" xyz="0 0 0" />
            <geometry>
                <mesh filename="package://omnicore_description/meshes/Yumi/coarse/link_5.stl" />
            </geometry>
            <material name="Grey" />
        </collision>
    </link>
    <!-- joint between link_5 and link_6 -->
    <joint name="joint_6" type="revolute">
        <parent link="link_5" />
        <child link="link_6" />
        <origin rpy="1.5707963267948966 0.0 0.0" xyz="-0.027 0 0.10039" />
        <axis xyz="0 0 1" />
        <limit effort="300" lower="-1.53588974175501" upper="2.4085543677521746" velocity="6.981317007977318" />
        <dynamics damping="0.5" />
    </joint>
    <link name="link_6">
        <inertial>
            <origin rpy="0 0 0" xyz="0 0 0" />
            <mass value="2" />
            <inertia ixx="0.1" ixy="0" ixz="0" iyy="0.1" iyz="0" izz="0.1" />
        </inertial>
        <visual>
            <origin rpy="0 0 0" xyz="0 0 0" />
            <geometry>
                <mesh filename="package://omnicore_description/meshes/Yumi/link_6.stl" />
            </geometry>
            <material name="Grey" />
        </visual>
        <collision>
            <origin rpy="0 0 0" xyz="0 0 0" />
            <geometry>
                <mesh filename="package://omnicore_description/meshes/Yumi/coarse/link_6.stl" />
            </geometry>
            <material name="Grey" />
        </collision>
    </link>
    <!-- joint between link_6 and link_7 -->
    <joint name="joint_7" type="revolute">
        <parent link="link_6" />
        <child link="link_7" />
        <origin rpy="-1.5707963267948966 0.0 0.0" xyz="0.027 0.029 0.0" />
        <axis xyz="0 0 1" />
        <limit effort="300" lower="-3.9968039870670142" upper="3.9968039870670142" velocity="6.981317007977318" />
        <dynamics damping="0.5" />
    </joint>
    <link name="link_7">
        <inertial>
            <origin rpy="0 0 0" xyz="0 0 0" />
            <mass value="2" />
            <inertia ixx="0.1" ixy="0" ixz="0" iyy="0.1" iyz="0" izz="0.1" />
        </inertial>
        <visual>
            <origin rpy="0 0 0" xyz="0 0 0" />
            <geometry>
                <mesh filename="package://omnicore_description/meshes/Yumi/link_7.stl" />
            </geometry>
            <material name="Grey" />
        </visual>
        <collision>
            <origin rpy="0 0 0" xyz="0 0 0" />
            <geometry>
                <mesh filename="package://omnicore_description/meshes/Yumi/coarse/link_7.stl" />
            </geometry>
            <material name="Grey" />
        </collision>
    </link>
    <transmission name="single_arm_tran_1">
        <type>transmission_interface/SimpleTransmission</type>
        <joint name="joint_1">
            <hardwareInterface>hardware_interface/PositionJointInterface</hardwareInterface>
        </joint>
        <actuator name="single_arm_motor_1">
            <hardwareInterface>hardware_interface/PositionJointInterface</hardwareInterface>
            <mechanicalReduction>1</mechanicalReduction>
        </actuator>
    </transmission>
    <transmission name="single_arm_tran_2">
        <type>transmission_interface/SimpleTransmission</type>
        <joint name="joint_2">
            <hardwareInterface>hardware_interface/PositionJointInterface</hardwareInterface>
        </joint>
        <actuator name="single_arm_motor_2">
            <hardwareInterface>hardware_interface/PositionJointInterface</hardwareInterface>
            <mechanicalReduction>1</mechanicalReduction>
        </actuator>
    </transmission>
    <transmission name="single_arm_tran_3">
        <type>transmission_interface/SimpleTransmission</type>
        <joint name="joint_3">
            <hardwareInterface>hardware_interface/PositionJointInterface</hardwareInterface>
        </joint>
        <actuator name="single_arm_motor_3">
            <hardwareInterface>hardware_interface/PositionJointInterface</hardwareInterface>
            <mechanicalReduction>1</mechanicalReduction>
        </actuator>
    </transmission>
    <transmission name="single_arm_tran_4">
        <type>transmission_interface/SimpleTransmission</type>
        <joint name="joint_4">
            <hardwareInterface>hardware_interface/PositionJointInterface</hardwareInterface>
        </joint>
        <actuator name="single_arm_motor_4">
            <hardwareInterface>hardware_interface/PositionJointInterface</hardwareInterface>
            <mechanicalReduction>1</mechanicalReduction>
        </actuator>
    </transmission>
    <transmission name="single_arm_tran_5">
        <type>transmission_interface/SimpleTransmission</type>
        <joint name="joint_5">
            <hardwareInterface>hardware_interface/PositionJointInterface</hardwareInterface>
        </joint>
        <actuator name="single_arm_motor_5">
            <hardwareInterface>hardware_interface/PositionJointInterface</hardwareInterface>
            <mechanicalReduction>1</mechanicalReduction>
        </actuator>
    </transmission>
    <transmission name="single_arm_tran_6">
        <type>transmission_interface/SimpleTransmission</type>
        <joint name="joint_6">
            <hardwareInterface>hardware_interface/PositionJointInterface</hardwareInterface>
        </joint>
        <actuator name="single_arm_motor_6">
            <hardwareInterface>hardware_interface/PositionJointInterface</hardwareInterface>
            <mechanicalReduction>1</mechanicalReduction>
        </actuator>
    </transmission>
    <transmission name="single_arm_tran_7">
        <type>transmission_interface/SimpleTransmission</type>
        <joint name="joint_7">
            <hardwareInterface>hardware_interface/PositionJointInterface</hardwareInterface>
        </joint>
        <actuator name="single_arm_motor_7">
            <hardwareInterface>hardware_interface/PositionJointInterface</hardwareInterface>
            <mechanicalReduction>1</mechanicalReduction>
        </actuator>
    </transmission>
    <!--joint
      between {parent} and base-->
    <joint name="link_7_joint" type="fixed">
        <origin rpy="0 0 0" xyz="0 0.0 0.0" />
        <parent link="link_7" />
        <child link="gripper_base" />
    </joint>
    <link name="gripper_base">
        <inertial>
            <origin rpy="0 0 0" xyz="0 0 0" />
            <mass value="0.2" />
            <inertia ixx="0.0001" ixy="0" ixz="0" iyy="0.0001" iyz="0" izz="0.0001" />
        </inertial>
        <visual>
            <origin rpy="0 0 0" xyz="0 0 0" />
            <geometry>
                <mesh filename="package://omnicore_description/meshes/Yumi/gripper/base.stl" />
            </geometry>
        </visual>
        <collision>
            <origin rpy="0 0 0" xyz="0 0 0" />
            <geometry>
                <mesh filename="package://omnicore_description/meshes/Yumi/gripper/coarse/base.stl" />
            </geometry>
        </collision>
    </link>
    <link name="grasp_link" />
    <joint name="grasp_joint" type="fixed">
        <origin rpy="0 0 0" xyz="0 0.0 0.13" />
        <child link="grasp_link" />
        <parent link="gripper_base" />
    </joint>
    <!-- joint between base and right finger -->
    <joint name="gripper_joint_r" type="prismatic">
        <parent link="gripper_base" />
        <child link="gripper_finger_r" />
        <origin rpy="0 0 0" xyz="0 -0.0065 0.0837" />
        <axis xyz="-1 0 0" />
        <limit effort="20" lower="0" upper="0.025" velocity="2" />
        <dynamics damping="1.0" />
    </joint>
    <link name="gripper_finger_r">
        <inertial>
            <origin rpy="0 0 0" xyz="0 0 0" />
            <mass value="0.1" />
            <inertia ixx="0.01" ixy="0" ixz="0" iyy="0.01" iyz="0" izz="0.01" />
        </inertial>
        <visual>
            <origin rpy="0 0 0" xyz="0 0 0" />
            <geometry>
                <mesh filename="package://omnicore_description/meshes/Yumi/gripper/finger.stl" />
            </geometry>
            <material name="Blue" />
        </visual>
        <collision>
            <origin rpy="0 0 0" xyz="0 0 0" />
            <geometry>
                <mesh filename="package://omnicore_description/meshes/Yumi/gripper/coarse/finger.stl" />
            </geometry>
            <material name="Blue" />
        </collision>
    </link>
    <!-- joint between base and left finger -->
    <joint name="gripper_joint_l" type="prismatic">
        <parent link="gripper_base" />
        <child link="gripper_finger_l" />
        <origin rpy="0 0 3.141592653589793" xyz="0 0.0065 0.0837" />
        <axis xyz="-1 0 0" />
        <limit effort="20" lower="0" upper="0.025" velocity="2" />
        <dynamics damping="1.0" />
    </joint>
    <link name="gripper_finger_l">
        <inertial>
            <origin rpy="0 0 0" xyz="0 0 0" />
            <mass value="0.1" />
            <inertia ixx="0.01" ixy="0" ixz="0" iyy="0.01" iyz="0" izz="0.01" />
        </inertial>
        <visual>
            <origin rpy="0 0 0" xyz="0 0 0" />
            <geometry>
                <mesh filename="package://omnicore_description/meshes/Yumi/gripper/finger.stl" />
            </geometry>
            <material name="Blue" />
        </visual>
        <collision>
            <origin rpy="0 0 0" xyz="0 0 0" />
            <geometry>
                <mesh filename="package://omnicore_description/meshes/Yumi/gripper/coarse/finger.stl" />
            </geometry>
            <material name="Blue" />
        </collision>
    </link>
    <transmission name="SmartGripper_tran">
        <type>transmission_interface/SimpleTransmission</type>
        <joint name="gripper_joint_l">
            <hardwareInterface>hardware_interface/EffortJointInterface</hardwareInterface>
        </joint>
        <actuator name="SmartGripper_motor_l">
            <hardwareInterface>hardware_interface/EffortJointInterface</hardwareInterface>
            <mechanicalReduction>1</mechanicalReduction>
        </actuator>
    </transmission>
    <transmission name="SmartGripper_tran">
        <type>transmission_interface/SimpleTransmission</type>
        <joint name="gripper_joint_r">
            <hardwareInterface>hardware_interface/EffortJointInterface</hardwareInterface>
        </joint>
        <actuator name="SmartGripper_motor_r">
            <hardwareInterface>hardware_interface/EffortJointInterface</hardwareInterface>
            <mechanicalReduction>1</mechanicalReduction>
        </actuator>
    </transmission>
    <gazebo reference="link_7_joint">
        <disableFixedJointLumping>true</disableFixedJointLumping>
        <preserveFixedJoint>true</preserveFixedJoint>
    </gazebo>
    <gazebo>
        <plugin filename="libgazebo_grasp_fix.so" name="gazebo_grasp_fix">
            <arm>
                <arm_name>yumi</arm_name>
                <palm_link>gripper_base</palm_link>
                <gripper_link>gripper_finger_l</gripper_link>
                <gripper_link>gripper_finger_r</gripper_link>
            </arm>
            <forces_angle_tolerance>100</forces_angle_tolerance>
            <update_rate>4</update_rate>
            <grip_count_threshold>4</grip_count_threshold>
            <max_grip_count>8</max_grip_count>
            <release_tolerance>0.005</release_tolerance>
            <disable_collisions_on_attach>false</disable_collisions_on_attach>
            <contact_topic>__default_topic__</contact_topic>
        </plugin>
    </gazebo>
    <gazebo>
        <plugin filename="libgazebo_ros_control.so" name="ros_control" />
    </gazebo>
</robot>

